Workbook

Sheet Calculator
A1: AVA containment break-even: validation workbook
A2: Blue cells are inputs. Every other number is a formula you can inspect. Enter the same inputs as the web page and compare.
A4: Supplied values (monthly basis)
A5: Inbound calls per month | B5: 96000
A6: Fully loaded agent cost (per agent, per month) | B6: 7000
A7: Agent occupancy rate | B7: 0.8
A8: Average call time (sec) | B8: 600
A9: Paid hours per agent per month (one FTE) | B9: 173
A10: % of agent time spent on these calls | B10: 0.75
A11: % of calls that go directly to an agent | B11: 0.1
A12: % of calls contained in IVR | B12: 0.2
A13: % of calls contained in AVA (target, % of ALL calls) | B13: 0.5
A14: IVR cost per call (only calls that never reach AVA) | B14: 0.5
A15: AVA cost per call (replaces the IVR fee) | B15: 1.2
A16: Charge AVA on escalated calls too (1 = yes, 0 = no) | B16: 1
... A20: Spread implementation over (months) | B20: 36
A22: Calculated values
A23: Agent calls per hour | B23: =3600/$B$8*$B$7 | E23: 3600 ÷ call time × occupancy
A24: Handle hours per FTE per month | B24: =$B$9*$B$10*$B$7 | E24: paid hours × % on these calls × occupancy
A25: Calls per FTE per month | B25: =B24*3600/$B$8 | E25: handle hours per FTE × 3600 ÷ call time
A26: Agent cost per call | B26: =$B$6/B25 | E26: agent cost ÷ calls per FTE per month
A27: % of calls reaching AVA | B27: =1-$B$11-$B$12 | E27: 100% − direct − IVR contained
A28: % IVR → AVA → Agent (at target) | B28: =B27-$B$13 | E28: reaching AVA − AVA contained
A29: Check: four paths add to 100% | B29: =$B$11+$B$12+$B$13+B28 | E29: must equal 100.0%
A30: AVA fixed cost per month | B30: =$B$18+$B$19/$B$20 | E30: platform fee + implementation ÷ months
A32: Monthly cost comparison | B32: Without AVA | C32: At target | D32: Change
A33: Agent-handled calls | B33: =($B$11+$B$27)*$B$5 | C33: =($B$11+$B$28)*$B$5 | D33: =C33-B33
A34: Agent handle hours | B34: =B33*$B$8/3600 | C34: =C33*$B$8/3600 | D34: =C34-B34
A35: Agent FTEs required | B35: =IF($B$17=1,ROUNDUP(B34/$B$24-0.000000001,0),B34/$B$24) | C35: =IF($B$17=1,ROUNDUP(C34/$B$24-0.000000001,0),C34/$B$24) | D35: =C35-B35
A36: Agent labor | B36: =B35*$B$6 | C36: =C35*$B$6 | D36: =C36-B36
A37: IVR cost | B37: =(1-$B$11)*$B$5*$B$14 | C37: =$B$12*$B$5*$B$14 | D37: =C37-B37
A38: AVA per-call cost | B38: =0 | C38: =IF($B$16=1,$B$27,$B$13)*$B$5*$B$15 | D38: =C38-B38
A39: AVA fixed cost | B39: =0 | C39: =$B$30 | D39: =C39-B39
A40: Total monthly cost | B40: =SUM(B36:B39) | C40: =SUM(C36:C39) | D40: =C40-B40
A42: Monthly savings at target | B42: =B40-C40
A43: Annual savings at target | B43: =B42*12
A45: Hours automated → FTEs saved → dollars (at target)
A46: Agent hours automated per month | B46: =$B$13*$B$5*$B$8/3600 | E46: AVA-contained calls × call time ÷ 3600
A47: FTEs saved (fractional) | B47: =B46/B24 | E47: hours automated ÷ handle hours per FTE
A48: FTEs saved (as staffed) | B48: =B35-C35 | E48: FTEs without AVA − FTEs at target (whole people if rounding is on)
...

Sheet Ladder
A1: AVA contained (% all calls) | B1: % of AVA calls | C1: IVR → AVA → Agent | D1: Agent calls | E1: FTEs needed | F1: AVA per-call cost | G1: Total monthly cost | H1: Monthly savings | I1: Agent hours automated | J1: FTEs saved
A2: =IF(0/1000<=Calculator!$B$27+0.0000001,0/1000,"") | B2: =IF(A2="","",A2/Calculator!$B$27) | C2: =IF(A2="","",Calculator!$B$27-A2) | D2: =IF(A2="","",(Calculator!$B$11+C2)*Calculator!$B$5) | E2: =IF(A2="","",IF(Calculator!$B$17=1,ROUNDUP(D2*Calculator!$B$8/3600/Calculator!$B$24-0.000000001,0),D2*Calculator!$B$8/3600/Calculator!$B$24)) | F2: =IF(A2="","",IF(Calculator!$B$16=1,Calculator!$B$27,A2)*Calculator!$B$5*Calculator!$B$15) | G2: =IF(A2="","",E2*Calculator!$B$6+Calculator!$C$37+F2+Calculator!$B$30) | H2: =IF(A2="","",Calculator!$B$40-G2) | I2: =IF(A2="","",A2*Calculator!$B$5*Calculator!$B$8/3600) | J2: =IF(A2="","",Calculator!$B$35-E2)
A3: =IF(1/1000<=Calculator!$B$27+0.0000001,1/1000,"") | B3: =IF(A3="","",A3/Calculator!$B$27) | C3: =IF(A3="","",Calculator!$B$27-A3) | D3: =IF(A3="","",(Calculator!$B$11+C3)*Calculator!$B$5) | E3: =IF(A3="","",IF(Calculator!$B$17=1,ROUNDUP(D3*Calculator!$B$8/3600/Calculator!$B$24-0.000000001,0),D3*Calculator!$B$8/3600/Calculator!$B$24)) | F3: =IF(A3="","",IF(Calculator!$B$16=1,Calculator!$B$27,A3)*Calculator!$B$5*Calculator!$B$15) | G3: =IF(A3="","",E3*Calculator!$B$6+Calculator!$C$37+F3+Calculator!$B$30) | H3: =IF(A3="","",Calculator!$B$40-G3) | I3: =IF(A3="","",A3*Calculator!$B$5*Calculator!$B$8/3600) | J3: =IF(A3="","",Calculator!$B$35-E3)
A4: =IF(2/1000<=Calculator!$B$27+0.0000001,2/1000,"") | B4: =IF(A4="","",A4/Calculator!$B$27) | C4: =IF(A4="","",Calculator!$B$27-A4) | D4: =IF(A4="","",(Calculator!$B$11+C4)*Calculator!$B$5) | E4: =IF(A4="","",IF(Calculator!$B$17=1,ROUNDUP(D4*Calculator!$B$8/3600/Calculator!$B$24-0.000000001,0),D4*Calculator!$B$8/3600/Calculator!$B$24)) | F4: =IF(A4="","",IF(Calculator!$B$16=1,Calculator!$B$27,A4)*Calculator!$B$5*Calculator!$B$15) | G4: =IF(A4="","",E4*Calculator!$B$6+Calculator!$C$37+F4+Calculator!$B$30) | H4: =IF(A4="","",Calculator!$B$40-G4) | I4: =IF(A4="","",A4*Calculator!$B$5*Calculator!$B$8/3600) | J4: =IF(A4="","",Calculator!$B$35-E4)
A5: =IF(3/1000<=Calculator!$B$27+0.0000001,3/1000,"") | B5: =IF(A5="","",A5/Calculator!$B$27) | C5: =IF(A5="","",Calculator!$B$27-A5) | D5: =IF(A5="","",(Calculator!$B$11+C5)*Calculator!$B$5) | E5: =IF(A5="","",IF(Calculator!$B$17=1,ROUNDUP(D5*Calculator!$B$8/3600/Calculator!$B$24-0.000000001,0),D5*Calculator!$B$8/3600/Calculator!$B$24)) | F5: =IF(A5="","",IF(Calculator!$B$16=1,Calculator!$B$27,A5)*Calculator!$B$5*Calculator!$B$15) | G5: =IF(A5="","",E5*Calculator!$B$6+Calculator!$C$37+F5+Calculator!$B$30) | H5: =IF(A5="","",Calculator!$B$40-G5) | I5: =IF(A5="","",A5*Calculator!$B$5*Calculator!$B$8/3600) | J5: =IF(A5="","",Calculator!$B$35-E5)
A6: =IF(4/1000<=Calculator!$B$27+0.0000001,4/1000,"") | B6: =IF(A6="","",A6/Calculator!$B$27) | C6: =IF(A6="","",Calculator!$B$27-A6) | D6: =IF(A6="","",(Calculator!$B$11+C6)*Calculator!$B$5) | E6: =IF(A6="","",IF(Calculator!$B$17=1,ROUNDUP(D6*Calculator!$B$8/3600/Calculator!$B$24-0.000000001,0),D6*Calculator!$B$8/3600/Calculator!$B$24)) | F6: =IF(A6="","",IF(Calculator!$B$16=1,Calculator!$B$27,A6)*Calculator!$B$5*Calculator!$B$15) | G6: =IF(A6="","",E6*Calculator!$B$6+Calculator!$C$37+F6+Calculator!$B$30) | H6: =IF(A6="","",Calculator!$B$40-G6) | I6: =IF(A6="","",A6*Calculator!$B$5*Calculator!$B$8/3600) | J6: =IF(A6="","",Calculator!$B$35-E6)
A7: =IF(5/1000<=Calculator!$B$27+0.0000001,5/1000,"") | B7: =IF(A7="","",A7/Calculator!$B$27) | C7: =IF(A7="","",Calculator!$B$27-A7) | D7: =IF(A7="","",(Calculator!$B$11+C7)*Calculator!$B$5) | E7: =IF(A7="","",IF(Calculator!$B$17=1,ROUNDUP(D7*Calculator!$B$8/3600/Calculator!$B$24-0.000000001,0),D7*Calculator!$B$8/3600/Calculator!$B$24)) | F7: =IF(A7="","",IF(Calculator!$B$16=1,Calculator!$B$27,A7)*Calculator!$B$5*Calculator!$B$15) | G7: =IF(A7="","",E7*Calculator!$B$6+Calculator!$C$37+F7+Calculator!$B$30) | H7: =IF(A7="","",Calculator!$B$40-G7) | I7: =IF(A7="","",A7*Calculator!$B$5*Calculator!$B$8/3600) | J7: =IF(A7="","",Calculator!$B$35-E7)
A8: =IF(6/1000<=Calculator!$B$27+0.0000001,6/1000,"") | B8: =IF(A8="","",A8/Calculator!$B$27) | C8: =IF(A8="","",Calculator!$B$27-A8) | D8: =IF(A8="","",(Calculator!$B$11+C8)*Calculator!$B$5) | E8: =IF(A8="","",IF(Calculator!$B$17=1,ROUNDUP(D8*Calculator!$B$8/3600/Calculator!$B$24-0.000000001,0),D8*Calculator!$B$8/3600/Calculator!$B$24)) | F8: =IF(A8="","",IF(Calculator!$B$16=1,Calculator!$B$27,A8)*Calculator!$B$5*Calculator!$B$15) | G8: =IF(A8="","",E8*Calculator!$B$6+Calculator!$C$37+F8+Calculator!$B$30) | H8: =IF(A8="","",Calculator!$B$40-G8) | I8: =IF(A8="","",A8*Calculator!$B$5*Calculator!$B$8/3600) | J8: =IF(A8="","",Calculator!$B$35-E8)
A9: =IF(7/1000<=Calculator!$B$27+0.0000001,7/1000,"") | B9: =IF(A9="","",A9/Calculator!$B$27) | C9: =IF(A9="","",Calculator!$B$27-A9) | D9: =IF(A9="","",(Calculator!$B$11+C9)*Calculator!$B$5) | E9: =IF(A9="","",IF(Calculator!$B$17=1,ROUNDUP(D9*Calculator!$B$8/3600/Calculator!$B$24-0.000000001,0),D9*Calculator!$B$8/3600/Calculator!$B$24)) | F9: =IF(A9="","",IF(Calculator!$B$16=1,Calculator!$B$27,A9)*Calculator!$B$5*Calculator!$B$15) | G9: =IF(A9="","",E9*Calculator!$B$6+Calculator!$C$37+F9+Calculator!$B$30) | H9: =IF(A9="","",Calculator!$B$40-G9) | I9: =IF(A9="","",A9*Calculator!$B$5*Calculator!$B$8/3600) | J9: =IF(A9="","",Calculator!$B$35-E9)
A10: =IF(8/1000<=Calculator!$B$27+0.0000001,8/1000,"") | B10: =IF(A10="","",A10/Calculator!$B$27) | C10: =IF(A10="","",Calculator!$B$27-A10) | D10: =IF(A10="","",(Calculator!$B$11+C10)*Calculator!$B$5) | E10: =IF(A10="","",IF(Calculator!$B$17=1,ROUNDUP(D10*Calculator!$B$8/3600/Calculator!$B$24-0.000000001,0),D10*Calculator!$B$8/3600/Calculator!$B$24)) | F10: =IF(A10="","",IF(Calculator!$B$16=1,Calculator!$B$27,A10)*Calculator!$B$5*Calculator!$B$15) | G10: =IF(A10="","",E10*Calculator!$B$6+Calculator!$C$37+F10+Calculator!$B$30) | H10: =IF(A10="","",Calculator!$B$40-G10) | I10: =IF(A10="","",A10*Calculator!$B$5*Calculator!$B$8/3600) | J10: =IF(A10="","",Calculator!$B$35-E10)
A11: =IF(9/1000<=Calculator!$B$27+0.0000001,9/1000,"") | B11: =IF(A11="","",A11/Calculator!$B$27) | C11: =IF(A11="","",Calculator!$B$27-A11) | D11: =IF(A11="","",(Calculator!$B$11+C11)*Calculator!$B$5) | E11: =IF(A11="","",IF(Calculator!$B$17=1,ROUNDUP(D11*Calculator!$B$8/3600/Calculator!$B$24-0.000000001,0),D11*Calculator!$B$8/3600/Calculator!$B$24)) | F11: =IF(A11="","",IF(Calculator!$B$16=1,Calculator!$B$27,A11)*Calculator!$B$5*Calculator!$B$15) | G11: =IF(A11="","",E11*Calculator!$B$6+Calculator!$C$37+F11+Calculator!$B$30) | H11: =IF(A11="","",Calculator!$B$40-G11) | I11: =IF(A11="","",A11*Calculator!$B$5*Calculator!$B$8/3600) | J11: =IF(A11="","",Calculator!$B$35-E11)
A12: =IF(10/1000<=Calculator!$B$27+0.0000001,10/1000,"") | B12: =IF(A12="","",A12/Calculator!$B$27) | C12: =IF(A12="","",Calculator!$B$27-A12) | D12: =IF(A12="","",(Calculator!$B$11+C12)*Calculator!$B$5) | E12: =IF(A12="","",IF(Calculator!$B$17=1,ROUNDUP(D12*Calculator!$B$8/3600/Calculator!$B$24-0.000000001,0),D12*Calculator!$B$8/3600/Calculator!$B$24)) | F12: =IF(A12="","",IF(Calculator!$B$16=1,Calculator!$B$27,A12)*Calculator!$B$5*Calculator!$B$15) | G12: =IF(A12="","",E12*Calculator!$B$6+Calculator!$C$37+F12+Calculator!$B$30) | H12: =IF(A12="","",Calculator!$B$40-G12) | I12: =IF(A12="","",A12*Calculator!$B$5*Calculator!$B$8/3600) | J12: =IF(A12="","",Calculator!$B$35-E12)
A13: =IF(11/1000<=Calculator!$B$27+0.0000001,11/1000,"") | B13: =IF(A13="","",A13/Calculator!$B$27) | C13: =IF(A13="","",Calculator!$B$27-A13) | D13: =IF(A13="","",(Calculator!$B$11+C13)*Calculator!$B$5) | E13: =IF(A13="","",IF(Calculator!$B$17=1,ROUNDUP(D13*Calculator!$B$8/3600/Calculator!$B$24-0.000000001,0),D13*Calculator!$B$8/3600/Calculator!$B$24)) | F13: =IF(A13="","",IF(Calculator!$B$16=1,Calculator!$B$27,A13)*Calculator!$B$5*Calculator!$B$15) | G13: =IF(A13="","",E13*Calculator!$B$6+Calculator!$C$37+F13+Calculator!$B$30) | H13: =IF(A13="","",Calculator!$B$40-G13) | I13: =IF(A13="","",A13*Calculator!$B$5*Calculator!$B$8/3600) | J13: =IF(A13="","",Calculator!$B$35-E13)
A14: =IF(12/1000<=Calculator!$B$27+0.0000001,12/1000,"") | B14: =IF(A14="","",A14/Calculator!$B$27) | C14: =IF(A14="","",Calculator!$B$27-A14) | D14: =IF(A14="","",(Calculator!$B$11+C14)*Calculator!$B$5) | E14: =IF(A14="","",IF(Calculator!$B$17=1,ROUNDUP(D14*Calculator!$B$8/3600/Calculator!$B$24-0.000000001,0),D14*Calculator!$B$8/3600/Calculator!$B$24)) | F14: =IF(A14="","",IF(Calculator!$B$16=1,Calculator!$B$27,A14)*Calculator!$B$5*Calculator!$B$15) | G14: =IF(A14="","",E14*Calculator!$B$6+Calculator!$C$37+F14+Calculator!$B$30) | H14: =IF(A14="","",Calculator!$B$40-G14) | I14: =IF(A14="","",A14*Calculator!$B$5*Calculator!$B$8/3600) | J14: =IF(A14="","",Calculator!$B$35-E14)
A15: =IF(13/1000<=Calculator!$B$27+0.0000001,13/1000,"") | B15: =IF(A15="","",A15/Calculator!$B$27) | C15: =IF(A15="","",Calculator!$B$27-A15) | D15: =IF(A15="","",(Calculator!$B$11+C15)*Calculator!$B$5) | E15: =IF(A15="","",IF(Calculator!$B$17=1,ROUNDUP(D15*Calculator!$B$8/3600/Calculator!$B$24-0.000000001,0),D15*Calculator!$B$8/3600/Calculator!$B$24)) | F15: =IF(A15="","",IF(Calculator!$B$16=1,Calculator!$B$27,A15)*Calculator!$B$5*Calculator!$B$15) | G15: =IF(A15="","",E15*Calculator!$B$6+Calculator!$C$37+F15+Calculator!$B$30) | H15: =IF(A15="","",Calculator!$B$40-G15) | I15: =IF(A15="","",A15*Calculator!$B$5*Calculator!$B$8/3600) | J15: =IF(A15="","",Calculator!$B$35-E15)
A16: =IF(14/1000<=Calculator!$B$27+0.0000001,14/1000,"") | B16: =IF(A16="","",A16/Calculator!$B$27) | C16: =IF(A16="","",Calculator!$B$27-A16) | D16: =IF(A16="","",(Calculator!$B$11+C16)*Calculator!$B$5) | E16: =IF(A16="","",IF(Calculator!$B$17=1,ROUNDUP(D16*Calculator!$B$8/3600/Calculator!$B$24-0.000000001,0),D16*Calculator!$B$8/3600/Calculator!$B$24)) | F16: =IF(A16="","",IF(Calculator!$B$16=1,Calculator!$B$27,A16)*Calculator!$B$5*Calculator!$B$15) | G16: =IF(A16="","",E16*Calculator!$B$6+Calculator!$C$37+F16+Calculator!$B$30) | H16: =IF(A16="","",Calculator!$B$40-G16) | I16: =IF(A16="","",A16*Calculator!$B$5*Calculator!$B$8/3600) | J16: =IF(A16="","",Calculator!$B$35-E16)
A17: =IF(15/1000<=Calculator!$B$27+0.0000001,15/1000,"") | B17: =IF(A17="","",A17/Calculator!$B$27) | C17: =IF(A17="","",Calculator!$B$27-A17) | D17: =IF(A17="","",(Calculator!$B$11+C17)*Calculator!$B$5) | E17: =IF(A17="","",IF(Calculator!$B$17=1,ROUNDUP(D17*Calculator!$B$8/3600/Calculator!$B$24-0.000000001,0),D17*Calculator!$B$8/3600/Calculator!$B$24)) | F17: =IF(A17="","",IF(Calculator!$B$16=1,Calculator!$B$27,A17)*Calculator!$B$5*Calculator!$B$15) | G17: =IF(A17="","",E17*Calculator!$B$6+Calculator!$C$37+F17+Calculator!$B$30) | H17: =IF(A17="","",Calculator!$B$40-G17) | I17: =IF(A17="","",A17*Calculator!$B$5*Calculator!$B$8/3600) | J17: =IF(A17="","",Calculator!$B$35-E17)
A18: =IF(16/1000<=Calculator!$B$27+0.0000001,16/1000,"") | B18: =IF(A18="","",A18/Calculator!$B$27) | C18: =IF(A18="","",Calculator!$B$27-A18) | D18: =IF(A18="","",(Calculator!$B$11+C18)*Calculator!$B$5) | E18: =IF(A18="","",IF(Calculator!$B$17=1,ROUNDUP(D18*Calculator!$B$8/3600/Calculator!$B$24-0.000000001,0),D18*Calculator!$B$8/3600/Calculator!$B$24)) | F18: =IF(A18="","",IF(Calculator!$B$16=1,Calculator!$B$27,A18)*Calculator!$B$5*Calculator!$B$15) | G18: =IF(A18="","",E18*Calculator!$B$6+Calculator!$C$37+F18+Calculator!$B$30) | H18: =IF(A18="","",Calculator!$B$40-G18) | I18: =IF(A18="","",A18*Calculator!$B$5*Calculator!$B$8/3600) | J18: =IF(A18="","",Calculator!$B$35-E18)
A19: =IF(17/1000<=Calculator!$B$27+0.0000001,17/1000,"") | B19: =IF(A19="","",A19/Calculator!$B$27) | C19: =IF(A19="","",Calculator!$B$27-A19) | D19: =IF(A19="","",(Calculator!$B$11+C19)*Calculator!$B$5) | E19: =IF(A19="","",IF(Calculator!$B$17=1,ROUNDUP(D19*Calculator!$B$8/3600/Calculator!$B$24-0.000000001,0),D19*Calculator!$B$8/3600/Calculator!$B$24)) | F19: =IF(A19="","",IF(Calculator!$B$16=1,Calculator!$B$27,A19)*Calculator!$B$5*Calculator!$B$15) | G19: =IF(A19="","",E19*Calculator!$B$6+Calculator!$C$37+F19+Calculator!$B$30) | H19: =IF(A19="","",Calculator!$B$40-G19) | I19: =IF(A19="","",A19*Calculator!$B$5*Calculator!$B$8/3600) | J19: =IF(A19="","",Calculator!$B$35-E19)
A20: =IF(18/1000<=Calculator!$B$27+0.0000001,18/1000,"") | B20: =IF(A20="","",A20/Calculator!$B$27) | C20: =IF(A20="","",Calculator!$B$27-A20) | D20: =IF(A20="","",(Calculator!$B$11+C20)*Calculator!$B$5) | E20: =IF(A20="","",IF(Calculator!$B$17=1,ROUNDUP(D20*Calculator!$B$8/3600/Calculator!$B$24-0.000000001,0),D20*Calculator!$B$8/3600/Calculator!$B$24)) | F20: =IF(A20="","",IF(Calculator!$B$16=1,Calculator!$B$27,A20)*Calculator!$B$5*Calculator!$B$15) | G20: =IF(A20="","",E20*Calculator!$B$6+Calculator!$C$37+F20+Calculator!$B$30) | H20: =IF(A20="","",Calculator!$B$40-G20) | I20: =IF(A20="","",A20*Calculator!$B$5*Calculator!$B$8/3600) | J20: =IF(A20="","",Calculator!$B$35-E20)
A21: =IF(19/1000<=Calculator!$B$27+0.0000001,19/1000,"") | B21: =IF(A21="","",A21/Calculator!$B$27) | C21: =IF(A21="","",Calculator!$B$27-A21) | D21: =IF(A21="","",(Calculator!$B$11+C21)*Calculator!$B$5) | E21: =IF(A21="","",IF(Calculator!$B$17=1,ROUNDUP(D21*Calculator!$B$8/3600/Calculator!$B$24-0.000000001,0),D21*Calculator!$B$8/3600/Calculator!$B$24)) | F21: =IF(A21="","",IF(Calculator!$B$16=1,Calculator!$B$27,A21)*Calculator!$B$5*Calculator!$B$15) | G21: =IF(A21="","",E21*Calculator!$B$6+Calculator!$C$37+F21+Calculator!$B$30) | H21: =IF(A21="","",Calculator!$B$40-G21) | I21: =IF(A21="","",A21*Calculator!$B$5*Calculator!$B$8/3600) | J21: =IF(A21="","",Calculator!$B$35-E21)
A22: =IF(20/1000<=Calculator!$B$27+0.0000001,20/1000,"") | B22: =IF(A22="","",A22/Calculator!$B$27) | C22: =IF(A22="","",Calculator!$B$27-A22) | D22: =IF(A22="","",(Calculator!$B$11+C22)*Calculator!$B$5) | E22: =IF(A22="","",IF(Calculator!$B$17=1,ROUNDUP(D22*Calculator!$B$8/3600/Calculator!$B$24-0.000000001,0),D22*Calculator!$B$8/3600/Calculator!$B$24)) | F22: =IF(A22="","",IF(Calculator!$B$16=1,Calculator!$B$27,A22)*Calculator!$B$5*Calculator!$B$15) | G22: =IF(A22="","",E22*Calculator!$B$6+Calculator!$C$37+F22+Calculator!$B$30) | H22: =IF(A22="","",Calculator!$B$40-G22) | I22: =IF(A22="","",A22*Calculator!$B$5*Calculator!$B$8/3600) | J22: =IF(A22="","",Calculator!$B$35-E22)
A23: =IF(21/1000<=Calculator!$B$27+0.0000001,21/1000,"") | B23: =IF(A23="","",A23/Calculator!$B$27) | C23: =IF(A23="","",Calculator!$B$27-A23) | D23: =IF(A23="","",(Calculator!$B$11+C23)*Calculator!$B$5) | E23: =IF(A23="","",IF(Calculator!$B$17=1,ROUNDUP(D23*Calculator!$B$8/3600/Calculator!$B$24-0.000000001,0),D23*Calculator!$B$8/3600/Calculator!$B$24)) | F23: =IF(A23="","",IF(Calculator!$B$16=1,Calculator!$B$27,A23)*Calculator!$B$5*Calculator!$B$15) | G23: =IF(A23="","",E23*Calculator!$B$6+Calculator!$C$37+F23+Calculator!$B$30) | H23: =IF(A23="","",Calculator!$B$40-G23) | I23: =IF(A23="","",A23*Calculator!$B$5*Calculator!$B$8/3600) | J23: =IF(A23="","",Calculator!$B$35-E23)
A24: =IF(22/1000<=Calculator!$B$27+0.0000001,22/1000,"") | B24: =IF(A24="","",A24/Calculator!$B$27) | C24: =IF(A24="","",Calculator!$B$27-A24) | D24: =IF(A24="","",(Calculator!$B$11+C24)*Calculator!$B$5) | E24: =IF(A24="","",IF(Calculator!$B$17=1,ROUNDUP(D24*Calculator!$B$8/3600/Calculator!$B$24-0.000000001,0),D24*Calculator!$B$8/3600/Calculator!$B$24)) | F24: =IF(A24="","",IF(Calculator!$B$16=1,Calculator!$B$27,A24)*Calculator!$B$5*Calculator!$B$15) | G24: =IF(A24="","",E24*Calculator!$B$6+Calculator!$C$37+F24+Calculator!$B$30) | H24: =IF(A24="","",Calculator!$B$40-G24) | I24: =IF(A24="","",A24*Calculator!$B$5*Calculator!$B$8/3600) | J24: =IF(A24="","",Calculator!$B$35-E24)
A25: =IF(23/1000<=Calculator!$B$27+0.0000001,23/1000,"") | B25: =IF(A25="","",A25/Calculator!$B$27) | C25: =IF(A25="","",Calculator!$B$27-A25) | D25: =IF(A25="","",(Calculator!$B$11+C25)*Calculator!$B$5) | E25: =IF(A25="","",IF(Calculator!$B$17=1,ROUNDUP(D25*Calculator!$B$8/3600/Calculator!$B$24-0.000000001,0),D25*Calculator!$B$8/3600/Calculator!$B$24)) | F25: =IF(A25="","",IF(Calculator!$B$16=1,Calculator!$B$27,A25)*Calculator!$B$5*Calculator!$B$15) | G25: =IF(A25="","",E25*Calculator!$B$6+Calculator!$C$37+F25+Calculator!$B$30) | H25: =IF(A25="","",Calculator!$B$40-G25) | I25: =IF(A25="","",A25*Calculator!$B$5*Calculator!$B$8/3600) | J25: =IF(A25="","",Calculator!$B$35-E25)
A26: =IF(24/1000<=Calculator!$B$27+0.0000001,24/1000,"") | B26: =IF(A26="","",A26/Calculator!$B$27) | C26: =IF(A26="","",Calculator!$B$27-A26) | D26: =IF(A26="","",(Calculator!$B$11+C26)*Calculator!$B$5) | E26: =IF(A26="","",IF(Calculator!$B$17=1,ROUNDUP(D26*Calculator!$B$8/3600/Calculator!$B$24-0.000000001,0),D26*Calculator!$B$8/3600/Calculator!$B$24)) | F26: =IF(A26="","",IF(Calculator!$B$16=1,Calculator!$B$27,A26)*Calculator!$B$5*Calculator!$B$15) | G26: =IF(A26="","",E26*Calculator!$B$6+Calculator!$C$37+F26+Calculator!$B$30) | H26: =IF(A26="","",Calculator!$B$40-G26) | I26: =IF(A26="","",A26*Calculator!$B$5*Calculator!$B$8/3600) | J26: =IF(A26="","",Calculator!$B$35-E26)
A27: =IF(25/1000<=Calculator!$B$27+0.0000001,25/1000,"") | B27: =IF(A27="","",A27/Calculator!$B$27) | C27: =IF(A27="","",Calculator!$B$27-A27) | D27: =IF(A27="","",(Calculator!$B$11+C27)*Calculator!$B$5) | E27: =IF(A27="","",IF(Calculator!$B$17=1,ROUNDUP(D27*Calculator!$B$8/3600/Calculator!$B$24-0.000000001,0),D27*Calculator!$B$8/3600/Calculator!$B$24)) | F27: =IF(A27="","",IF(Calculator!$B$16=1,Calculator!$B$27,A27)*Calculator!$B$5*Calculator!$B$15) | G27: =IF(A27="","",E27*Calculator!$B$6+Calculator!$C$37+F27+Calculator!$B$30) | H27: =IF(A27="","",Calculator!$B$40-G27) | I27: =IF(A27="","",A27*Calculator!$B$5*Calculator!$B$8/3600) | J27: =IF(A27="","",Calculator!$B$35-E27)
A28: =IF(26/1000<=Calculator!$B$27+0.0000001,26/1000,"") | B28: =IF(A28="","",A28/Calculator!$B$27) | C28: =IF(A28="","",Calculator!$B$27-A28) | D28: =IF(A28="","",(Calculator!$B$11+C28)*Calculator!$B$5) | E28: =IF(A28="","",IF(Calculator!$B$17=1,ROUNDUP(D28*Calculator!$B$8/3600/Calculator!$B$24-0.000000001,0),D28*Calculator!$B$8/3600/Calculator!$B$24)) | F28: =IF(A28="","",IF(Calculator!$B$16=1,Calculator!$B$27,A28)*Calculator!$B$5*Calculator!$B$15) | G28: =IF(A28="","",E28*Calculator!$B$6+Calculator!$C$37+F28+Calculator!$B$30) | H28: =IF(A28="","",Calculator!$B$40-G28) | I28: =IF(A28="","",A28*Calculator!$B$5*Calculator!$B$8/3600) | J28: =IF(A28="","",Calculator!$B$35-E28)
A29: =IF(27/1000<=Calculator!$B$27+0.0000001,27/1000,"") | B29: =IF(A29="","",A29/Calculator!$B$27) | C29: =IF(A29="","",Calculator!$B$27-A29) | D29: =IF(A29="","",(Calculator!$B$11+C29)*Calculator!$B$5) | E29: =IF(A29="","",IF(Calculator!$B$17=1,ROUNDUP(D29*Calculator!$B$8/3600/Calculator!$B$24-0.000000001,0),D29*Calculator!$B$8/3600/Calculator!$B$24)) | F29: =IF(A29="","",IF(Calculator!$B$16=1,Calculator!$B$27,A29)*Calculator!$B$5*Calculator!$B$15) | G29: =IF(A29="","",E29*Calculator!$B$6+Calculator!$C$37+F29+Calculator!$B$30) | H29: =IF(A29="","",Calculator!$B$40-G29) | I29: =IF(A29="","",A29*Calculator!$B$5*Calculator!$B$8/3600) | J29: =IF(A29="","",Calculator!$B$35-E29)
A30: =IF(28/1000<=Calculator!$B$27+0.0000001,28/1000,"") | B30: =IF(A30="","",A30/Calculator!$B$27) | C30: =IF(A30="","",Calculator!$B$27-A30) | D30: =IF(A30="","",(Calculator!$B$11+C30)*Calculator!$B$5) | E30: =IF(A30="","",IF(Calculator!$B$17=1,ROUNDUP(D30*Calculator!$B$8/3600/Calculator!$B$24-0.000000001,0),D30*Calculator!$B$8/3600/Calculator!$B$24)) | F30: =IF(A30="","",IF(Calculator!$B$16=1,Calculator!$B$27,A30)*Calculator!$B$5*Calculator!$B$15) | G30: =IF(A30="","",E30*Calculator!$B$6+Calculator!$C$37+F30+Calculator!$B$30) | H30: =IF(A30="","",Calculator!$B$40-G30) | I30: =IF(A30="","",A30*Calculator!$B$5*Calculator!$B$8/3600) | J30: =IF(A30="","",Calculator!$B$35-E30)
A31: =IF(29/1000<=Calculator!$B$27+0.0000001,29/1000,"") | B31: =IF(A31="","",A31/Calculator!$B$27) | C31: =IF(A31="","",Calculator!$B$27-A31) | D31: =IF(A31="","",(Calculator!$B$11+C31)*Calculator!$B$5) | E31: =IF(A31="","",IF(Calculator!$B$17=1,ROUNDUP(D31*Calculator!$B$8/3600/Calculator!$B$24-0.000000001,0),D31*Calculator!$B$8/3600/Calculator!$B$24)) | F31: =IF(A31="","",IF(Calculator!$B$16=1,Calculator!$B$27,A31)*Calculator!$B$5*Calculator!$B$15) | G31: =IF(A31="","",E31*Calculator!$B$6+Calculator!$C$37+F31+Calculator!$B$30) | H31: =IF(A31="","",Calculator!$B$40-G31) | I31: =IF(A31="","",A31*Calculator!$B$5*Calculator!$B$8/3600) | J31: =IF(A31="","",Calculator!$B$35-E31)
A32: =IF(30/1000<=Calculator!$B$27+0.0000001,30/1000,"") | B32: =IF(A32="","",A32/Calculator!$B$27) | C32: =IF(A32="","",Calculator!$B$27-A32) | D32: =IF(A32="","",(Calculator!$B$11+C32)*Calculator!$B$5) | E32: =IF(A32="","",IF(Calculator!$B$17=1,ROUNDUP(D32*Calculator!$B$8/3600/Calculator!$B$24-0.000000001,0),D32*Calculator!$B$8/3600/Calculator!$B$24)) | F32: =IF(A32="","",IF(Calculator!$B$16=1,Calculator!$B$27,A32)*Calculator!$B$5*Calculator!$B$15) | G32: =IF(A32="","",E32*Calculator!$B$6+Calculator!$C$37+F32+Calculator!$B$30) | H32: =IF(A32="","",Calculator!$B$40-G32) | I32: =IF(A32="","",A32*Calculator!$B$5*Calculator!$B$8/3600) | J32: =IF(A32="","",Calculator!$B$35-E32)
A33: =IF(31/1000<=Calculator!$B$27+0.0000001,31/1000,"") | B33: =IF(A33="","",A33/Calculator!$B$27) | C33: =IF(A33="","",Calculator!$B$27-A33) | D33: =IF(A33="","",(Calculator!$B$11+C33)*Calculator!$B$5) | E33: =IF(A33="","",IF(Calculator!$B$17=1,ROUNDUP(D33*Calculator!$B$8/3600/Calculator!$B$24-0.000000001,0),D33*Calculator!$B$8/3600/Calculator!$B$24)) | F33: =IF(A33="","",IF(Calculator!$B$16=1,Calculator!$B$27,A33)*Calculator!$B$5*Calculator!$B$15) | G33: =IF(A33="","",E33*Calculator!$B$6+Calculator!$C$37+F33+Calculator!$B$30) | H33: =IF(A33="","",Calculator!$B$40-G33) | I33: =IF(A33="","",A33*Calculator!$B$5*Calculator!$B$8/3600) | J33: =IF(A33="","",Calculator!$B$35-E33)
A34: =IF(32/1000<=Calculator!$B$27+0.0000001,32/1000,"") | B34: =IF(A34="","",A34/Calculator!$B$27) | C34: =IF(A34="","",Calculator!$B$27-A34) | D34: =IF(A34="","",(Calculator!$B$11+C34)*Calculator!$B$5) | E34: =IF(A34="","",IF(Calculator!$B$17=1,ROUNDUP(D34*Calculator!$B$8/3600/Calculator!$B$24-0.000000001,0),D34*Calculator!$B$8/3600/Calculator!$B$24)) | F34: =IF(A34="","",IF(Calculator!$B$16=1,Calculator!$B$27,A34)*Calculator!$B$5*Calculator!$B$15) | G34: =IF(A34="","",E34*Calculator!$B$6+Calculator!$C$37+F34+Calculator!$B$30) | H34: =IF(A34="","",Calculator!$B$40-G34) | I34: =IF(A34="","",A34*Calculator!$B$5*Calculator!$B$8/3600) | J34: =IF(A34="","",Calculator!$B$35-E34)
A35: =IF(33/1000<=Calculator!$B$27+0.0000001,33/1000,"") | B35: =IF(A35="","",A35/Calculator!$B$27) | C35: =IF(A35="","",Calculator!$B$27-A35) | D35: =IF(A35="","",(Calculator!$B$11+C35)*Calculator!$B$5) | E35: =IF(A35="","",IF(Calculator!$B$17=1,ROUNDUP(D35*Calculator!$B$8/3600/Calculator!$B$24-0.000000001,0),D35*Calculator!$B$8/3600/Calculator!$B$24)) | F35: =IF(A35="","",IF(Calculator!$B$16=1,Calculator!$B$27,A35)*Calculator!$B$5*Calculator!$B$15) | G35: =IF(A35="","",E35*Calculator!$B$6+Calculator!$C$37+F35+Calculator!$B$30) | H35: =IF(A35="","",Calculator!$B$40-G35) | I35: =IF(A35="","",A35*Calculator!$B$5*Calculator!$B$8/3600) | J35: =IF(A35="","",Calculator!$B$35-E35)
A36: =IF(34/1000<=Calculator!$B$27+0.0000001,34/1000,"") | B36: =IF(A36="","",A36/Calculator!$B$27) | C36: =IF(A36="","",Calculator!$B$27-A36) | D36: =IF(A36="","",(Calculator!$B$11+C36)*Calculator!$B$5) | E36: =IF(A36="","",IF(Calculator!$B$17=1,ROUNDUP(D36*Calculator!$B$8/3600/Calculator!$B$24-0.000000001,0),D36*Calculator!$B$8/3600/Calculator!$B$24)) | F36: =IF(A36="","",IF(Calculator!$B$16=1,Calculator!$B$27,A36)*Calculator!$B$5*Calculator!$B$15) | G36: =IF(A36="","",E36*Calculator!$B$6+Calculator!$C$37+F36+Calculator!$B$30) | H36: =IF(A36="","",Calculator!$B$40-G36) | I36: =IF(A36="","",A36*Calculator!$B$5*Calculator!$B$8/3600) | J36: =IF(A36="","",Calculator!$B$35-E36)
A37: =IF(35/1000<=Calculator!$B$27+0.0000001,35/1000,"") | B37: =IF(A37="","",A37/Calculator!$B$27) | C37: =IF(A37="","",Calculator!$B$27-A37) | D37: =IF(A37="","",(Calculator!$B$11+C37)*Calculator!$B$5) | E37: =IF(A37="","",IF(Calculator!$B$17=1,ROUNDUP(D37*Calculator!$B$8/3600/Calculator!$B$24-0.000000001,0),D37*Calculator!$B$8/3600/Calculator!$B$24)) | F37: =IF(A37="","",IF(Calculator!$B$16=1,Calculator!$B$27,A37)*Calculator!$B$5*Calculator!$B$15) | G37: =IF(A37="","",E37*Calculator!$B$6+Calculator!$C$37+F37+Calculator!$B$30) | H37: =IF(A37="","",Calculator!$B$40-G37) | I37: =IF(A37="","",A37*Calculator!$B$5*Calculator!$B$8/3600) | J37: =IF(A37="","",Calculator!$B$35-E37)
A38: =IF(36/1000<=Calculator!$B$27+0.0000001,36/1000,"") | B38: =IF(A38="","",A38/Calculator!$B$27) | C38: =IF(A38="","",Calculator!$B$27-A38) | D38: =IF(A38="","",(Calculator!$B$11+C38)*Calculator!$B$5) | E38: =IF(A38="","",IF(Calculator!$B$17=1,ROUNDUP(D38*Calculator!$B$8/3600/Calculator!$B$24-0.000000001,0),D38*Calculator!$B$8/3600/Calculator!$B$24)) | F38: =IF(A38="","",IF(Calculator!$B$16=1,Calculator!$B$27,A38)*Calculator!$B$5*Calculator!$B$15) | G38: =IF(A38="","",E38*Calculator!$B$6+Calculator!$C$37+F38+Calculator!$B$30) | H38: =IF(A38="","",Calculator!$B$40-G38) | I38: =IF(A38="","",A38*Calculator!$B$5*Calculator!$B$8/3600) | J38: =IF(A38="","",Calculator!$B$35-E38)
A39: =IF(37/1000<=Calculator!$B$27+0.0000001,37/1000,"") | B39: =IF(A39="","",A39/Calculator!$B$27) | C39: =IF(A39="","",Calculator!$B$27-A39) | D39: =IF(A39="","",(Calculator!$B$11+C39)*Calculator!$B$5) | E39: =IF(A39="","",IF(Calculator!$B$17=1,ROUNDUP(D39*Calculator!$B$8/3600/Calculator!$B$24-0.000000001,0),D39*Calculator!$B$8/3600/Calculator!$B$24)) | F39: =IF(A39="","",IF(Calculator!$B$16=1,Calculator!$B$27,A39)*Calculator!$B$5*Calculator!$B$15) | G39: =IF(A39="","",E39*Calculator!$B$6+Calculator!$C$37+F39+Calculator!$B$30) | H39: =IF(A39="","",Calculator!$B$40-G39) | I39: =IF(A39="","",A39*Calculator!$B$5*Calculator!$B$8/3600) | J39: =IF(A39="","",Calculator!$B$35-E39)
A40: =IF(38/1000<=Calculator!$B$27+0.0000001,38/1000,"") | B40: =IF(A40="","",A40/Calculator!$B$27) | C40: =IF(A40="","",Calculator!$B$27-A40) | D40: =IF(A40="","",(Calculator!$B$11+C40)*Calculator!$B$5) | E40: =IF(A40="","",IF(Calculator!$B$17=1,ROUNDUP(D40*Calculator!$B$8/3600/Calculator!$B$24-0.000000001,0),D40*Calculator!$B$8/3600/Calculator!$B$24)) | F40: =IF(A40="","",IF(Calculator!$B$16=1,Calculator!$B$27,A40)*Calculator!$B$5*Calculator!$B$15) | G40: =IF(A40="","",E40*Calculator!$B$6+Calculator!$C$37+F40+Calculator!$B$30) | H40: =IF(A40="","",Calculator!$B$40-G40) | I40: =IF(A40="","",A40*Calculator!$B$5*Calculator!$B$8/3600) | J40: =IF(A40="","",Calculator!$B$35-E40)
...

Sheet Checks
A1: Sanity check | B1: Expected | C1: Workbook | D1: Pass?
A2: Four paths add to 100% | B2: =1 | C2: =Calculator!B29 | D2: =IF(ABS(B2-C2)<0.01,"PASS","FAIL")
A3: At 0% AVA: FTEs equal FTEs without AVA | B3: =Calculator!B35 | C3: =INDEX(Ladder!E:E,MATCH(ROUND(0,3),Ladder!A:A,0)) | D3: =IF(ABS(B3-C3)<0.01,"PASS","FAIL")
A4: At 0% AVA: savings = IVR fees avoided − (AVA per-call cost + fixed) when AVA is charged on escalations | B4: =Calculator!$B$27*Calculator!$B$5*Calculator!$B$14-(IF(Calculator!$B$16=1,Calculator!$B$27*Calculator!$B$5*Calculator!$B$15,0)+Calculator!B30) | C4: =INDEX(Ladder!H:H,MATCH(ROUND(0,3),Ladder!A:A,0)) | D4: =IF(ABS(B4-C4)<0.01,"PASS","FAIL")
A5: At break-even: savings are zero or slightly positive | B5: ≥ 0 | C5: =INDEX(Ladder!H:H,MATCH(ROUND(Calculator!B55,3),Ladder!A:A,0)) | D5: =IF(C5>=0,"PASS","FAIL")
A6: One step (0.1%) below break-even: savings are negative | B6: < 0 | C6: =IF(Calculator!B55=0,"n/a",INDEX(Ladder!H:H,MATCH(ROUND(Calculator!B55-0.001,3),Ladder!A:A,0))) | D6: =IF(C6="n/a","n/a",IF(C6<0,"PASS","FAIL"))
A7: At maximum AVA (all calls reaching AVA contained): only direct calls need FTEs | B7: =IF(Calculator!$B$17=1,ROUNDUP(Calculator!$B$11*Calculator!$B$5*Calculator!$B$8/3600/Calculator!B24-0.000000001,0),Calculator!$B$11*Calculator!$B$5*Calculator!$B$8/3600/Calculator!B24) | C7: =INDEX(Ladder!E:E,MATCH(ROUND(Calculator!$B$27,3),Ladder!A:A,0)) | D7: =IF(ABS(B7-C7)<0.01,"PASS","FAIL")
A8: Hours chain: labor saved + IVR avoided − AVA cost = total cost difference | B8: =Calculator!B42 | C8: =Calculator!B52 | D8: =IF(ABS(B8-C8)<0.01,"PASS","FAIL")
A9: Fractional FTEs: FTEs saved = hours automated ÷ handle hours per FTE | B9: =Calculator!B47 | C9: =IF(Calculator!$B$17=1,"turn rounding off",Calculator!B48) | D9: =IF(ISNUMBER(C9),IF(ABS(B9-C9)<0.01,"PASS","FAIL"),"n/a")
A10: Fractional agents: labor = agent calls × agent cost per call | B10: =Calculator!B33*Calculator!B26 | C10: =IF(Calculator!$B$17=1,"turn rounding off",Calculator!B36) | D10: =IF(ISNUMBER(C10),IF(ABS(B10-C10)<0.01,"PASS","FAIL"),"n/a")
A12: The 0%-AVA savings check assumes 0% AVA leaves agents unchanged, which holds because both sides then route the same calls to agents.
